Workbook

Sheet Products
B2: Worksheet 1
B4: Product ID | C4: Product | D4: Price
B5: 101 | C5: Product A | D5: 120
B6: 102 | C6: Product B | D6: 150
B7: 103 | C7: Product C | D7: 200
B8: 104 | C8: Product D | D8: 90
B9: 105 | C9: Product E | D9: 220
B10: 106 | C10: Product F | D10: 130

Sheet Orders
B2: Worksheet 2
G3: 1. Use VLOOKUP to find the product names for each ProductID in the Orders worksheet.
B4: Order ID | C4: Product ID | D4: Quantity | G4: Order ID | H4: Product ID | I4: Quantity | J4: Product Name
B5: 1 | C5: 101 | D5: 2 | G5: 1 | H5: 101 | I5: 2 | J5: =VLOOKUP(H5,Products!$B$4:$D$10,2,0) -> Product A
B6: 2 | C6: 103 | D6: 1 | G6: 2 | H6: 103 | I6: 1 | J6: =VLOOKUP(H6,Products!$B$4:$D$10,2,0) -> Product C
B7: 3 | C7: 105 | D7: 4 | G7: 3 | H7: 105 | I7: 4 | J7: =VLOOKUP(H7,Products!$B$4:$D$10,2,0) -> Product E
B8: 4 | C8: 106 | D8: 3 | G8: 4 | H8: 106 | I8: 3 | J8: =VLOOKUP(H8,Products!$B$4:$D$10,2,0) -> Product F
B9: 5 | C9: 102 | D9: 5 | G9: 5 | H9: 102 | I9: 5 | J9: =VLOOKUP(H9,Products!$B$4:$D$10,2,0) -> Product B
B10: 6 | C10: 104 | D10: 6 | G10: 6 | H10: 104 | I10: 6 | J10: =VLOOKUP(H10,Products!$B$4:$D$10,2,0) -> Product D
G13: 2. Use VLOOKUP to find the price for each ProductID in the Orders worksheet, then calculate the TotalPrice by multiplying the Quantity by the Product Price.
G14: Order ID | H14: Product ID | I14: Quantity | J14: Price | K14: Total Price
G15: 1 | H15: 101 | I15: 2 | J15: =VLOOKUP(H15,Products!$B$4:$D$10,3,0) -> 120 | K15: =I15*J15 -> 240
G16: 2 | H16: 103 | I16: 1 | J16: =VLOOKUP(H16,Products!$B$4:$D$10,3,0) -> 200 | K16: =I16*J16 -> 200
G17: 3 | H17: 105 | I17: 4 | J17: =VLOOKUP(H17,Products!$B$4:$D$10,3,0) -> 220 | K17: =I17*J17 -> 880
G18: 4 | H18: 106 | I18: 3 | J18: =VLOOKUP(H18,Products!$B$4:$D$10,3,0) -> 130 | K18: =I18*J18 -> 390
G19: 5 | H19: 102 | I19: 5 | J19: =VLOOKUP(H19,Products!$B$4:$D$10,3,0) -> 150 | K19: =I19*J19 -> 750
G20: 6 | H20: 104 | I20: 6 | J20: =VLOOKUP(H20,Products!$B$4:$D$10,3,0) -> 90 | K20: =I20*J20 -> 540
G23: 3. Use VLOOKUP to check if there are any ProductIDs in the Orders worksheet that do not exist in the Products worksheet.
B24: Order ID | C24: Product ID | D24: Quantity | G24: Order ID | H24: Product ID | I24: Quantity | J24: Product exists or not
B25: 1 | C25: 101 | D25: 2 | G25: 1 | H25: 101 | I25: 2 | J25: =IF(ISNA(VLOOKUP(H25,Products!$B$4:$D$10,1,0)),"Not Exist","Exists") -> Exists
B26: 2 | C26: 103 | D26: 1 | G26: 2 | H26: 103 | I26: 1 | J26: =IF(ISNA(VLOOKUP(H26,Products!$B$4:$D$10,1,0)),"Not Exist","Exists") -> Exists
B27: 3 | C27: 105 | D27: 4 | G27: 3 | H27: 105 | I27: 4 | J27: =IF(ISNA(VLOOKUP(H27,Products!$B$4:$D$10,1,0)),"Not Exist","Exists") -> Exists
B28: 4 | C28: 106 | D28: 3 | G28: 4 | H28: 106 | I28: 3 | J28: =IF(ISNA(VLOOKUP(H28,Products!$B$4:$D$10,1,0)),"Not Exist","Exists") -> Exists
B29: 5 | C29: 102 | D29: 5 | G29: 5 | H29: 102 | I29: 5 | J29: =IF(ISNA(VLOOKUP(H29,Products!$B$4:$D$10,1,0)),"Not Exist","Exists") -> Exists
B30: 6 | C30: 104 | D30: 6 | G30: 6 | H30: 104 | I30: 6 | J30: =IF(ISNA(VLOOKUP(H30,Products!$B$4:$D$10,1,0)),"Not Exist","Exists") -> Exists
B31: 7 | C31: 107 | D31: 7 | G31: 7 | H31: 107 | I31: 7 | J31: =IF(ISNA(VLOOKUP(H31,Products!$B$4:$D$10,1,0)),"Not Exist","Exists") -> Not Exist
G34: 4. Assume a discount of 10% is given on all products. Use VLOOKUP to find the original price and then calculate the discounted price.
G35: Order ID | H35: Product ID | I35: Quantity | J35: Original Price | K35: Discount Amount (10%) | L35: Discounted Price
G36: 1 | H36: 101 | I36: 2 | J36: =VLOOKUP(H36,Products!$B$4:$D$10,3,0) -> 120 | K36: =J36*10% -> 12 | L36: =J36-K36 -> 108
G37: 2 | H37: 103 | I37: 1 | J37: =VLOOKUP(H37,Products!$B$4:$D$10,3,0) -> 200 | K37: =J37*10% -> 20 | L37: =J37-K37 -> 180
G38: 3 | H38: 105 | I38: 4 | J38: =VLOOKUP(H38,Products!$B$4:$D$10,3,0) -> 220 | K38: =J38*10% -> 22 | L38: =J38-K38 -> 198
G39: 4 | H39: 106 | I39: 3 | J39: =VLOOKUP(H39,Products!$B$4:$D$10,3,0) -> 130 | K39: =J39*10% -> 13 | L39: =J39-K39 -> 117
G40: 5 | H40: 102 | I40: 5 | J40: =VLOOKUP(H40,Products!$B$4:$D$10,3,0) -> 150 | K40: =J40*10% -> 15 | L40: =J40-K40 -> 135
G41: 6 | H41: 104 | I41: 6 | J41: =VLOOKUP(H41,Products!$B$4:$D$10,3,0) -> 90 | K41: =J41*10% -> 9 | L41: =J41-K41 -> 81
G44: 5. Use VLOOKUP to find the price for each ProductID and then calculate the order value. Find the maximum order value from the list.
G45: Order ID | H45: Product ID | I45: Quantity | J45: Price | K45: Order value
G46: 1 | H46: 101 | I46: 2 | J46: =VLOOKUP(H46,Products!$B$4:$D$10,3,0) -> 120 | K46: =I46*J46 -> 240
G47: 2 | H47: 103 | I47: 1 | J47: =VLOOKUP(H47,Products!$B$4:$D$10,3,0) -> 200 | K47: =I47*J47 -> 200
G48: 3 | H48: 105 | I48: 4 | J48: =VLOOKUP(H48,Products!$B$4:$D$10,3,0) -> 220 | K48: =I48*J48 -> 880 | L48: Max Order Value: | M48: =MAX(K46:K51) -> 880
G49: 4 | H49: 106 | I49: 3 | J49: =VLOOKUP(H49,Products!$B$4:$D$10,3,0) -> 130 | K49: =I49*J49 -> 390
...
