Workbook

Sheet Cell_Reference (Mixed)
B1: 1 | C1: 2 | D1: 3 | E1: 4 | F1: 5
A2: 10 | B2: =$A2*B$1 -> 10 | C2: =$A2*C$1 -> 20 | D2: =$A2*D$1 -> 30 | E2: =$A2*E$1 -> 40 | F2: =$A2*F$1 -> 50
A3: 20 | B3: =$A3*B$1 -> 20 | C3: =$A3*C$1 -> 40 | D3: =$A3*D$1 -> 60 | E3: =$A3*E$1 -> 80 | F3: =$A3*F$1 -> 100
A4: 30 | B4: =$A4*B$1 -> 30 | C4: =$A4*C$1 -> 60 | D4: =$A4*D$1 -> 90 | E4: =$A4*E$1 -> 120 | F4: =$A4*F$1 -> 150
A5: 40 | B5: =$A5*B$1 -> 40 | C5: =$A5*C$1 -> 80 | D5: =$A5*D$1 -> 120 | E5: =$A5*E$1 -> 160 | F5: =$A5*F$1 -> 200
A6: 50 | B6: =$A6*B$1 -> 50 | C6: =$A6*C$1 -> 100 | D6: =$A6*D$1 -> 150 | E6: =$A6*E$1 -> 200 | F6: =$A6*F$1 -> 250

Sheet Copy_paste
B2: Order ID | C2: Product | D2: Price | E2: Quantity | G2: Order ID | H2: Product | I2: Price | J2: Quantity
B3: 1001 | C3: Pen | D3: 10 | E3: 5 | G3: 1001 | H3: Pen | I3: 10 | J3: 5
B4: 1002 | C4: Pencil | D4: 5 | E4: 10 | G4: 1002 | H4: Pencil | I4: 5 | J4: 10
B5: 1003 | C5: Notebook | D5: 50 | E5: 3 | G5: 1003 | H5: Notebook | I5: 50 | J5: 3
B6: 1004 | C6: Eraser | D6: 3 | E6: 20 | G6: 1004 | H6: Eraser | I6: 3 | J6: 20
B7: 1005 | C7: Marker | D7: 25 | E7: 4 | G7: 1005 | H7: Marker | I7: 25 | J7: 4
B8: 1006 | C8: Scale | D8: 15 | E8: 6 | G8: 1006 | H8: Scale | I8: 15 | J8: 6
B9: 1007 | C9: Sharpner | D9: 8 | E9: 8 | G9: 1007 | H9: Sharpner | I9: 8 | J9: 8
B10: 1008 | C10: File | D10: 40 | E10: 2 | G10: 1008 | H10: File | I10: 40 | J10: 2
B14: Order ID | C14: 1001 | D14: 1002 | E14: 1003 | F14: 1004 | G14: 1005 | H14: 1006 | I14: 1007 | J14: 1008
B15: Product | C15: Pen | D15: Pencil | E15: Notebook | F15: Eraser | G15: Marker | H15: Scale | I15: Sharpner | J15: File
B16: Price | C16: 10 | D16: 5 | E16: 50 | F16: 3 | G16: 25 | H16: 15 | I16: 8 | J16: 40
B17: Quantity | C17: 5 | D17: 10 | E17: 3 | F17: 20 | G17: 4 | H17: 6 | I17: 8 | J17: 2

Sheet Fill_Series
D2: Monday | E2: Monday | F2: Monday | G2: Monday | I2: 10 | J2: 10 | M2: 10 | N2: 10 | O2: 10 | P2: 10 | Q2: 10
D3: Tuesday | E3: Tuesday | F3: Tuesday | I3: 10 | J3: 20 | M3: 10 | N3: 10 | O3: 10 | P3: 10 | Q3: 10
D4: Wednesday | E4: Wednesday | F4: Wednesday | I4: 10 | J4: 30 | M4: 10 | N4: 10 | O4: 10 | P4: 10 | Q4: 10
D5: Thursday | E5: Thursday | F5: Thursday | I5: 10 | J5: 40 | M5: 10 | N5: 10 | O5: 10 | P5: 10 | Q5: 10
D6: Friday | E6: Friday | F6: Friday | I6: 10 | J6: 50 | M6: 10 | N6: 10 | O6: 10 | P6: 10 | Q6: 10
D7: Saturday | E7: Saturday | F7: Monday | I7: 10 | J7: 60 | M7: 10 | N7: 10 | O7: 10 | P7: 10 | Q7: 10
D8: Sunday | E8: Sunday | F8: Tuesday | I8: 10 | J8: 70 | M8: 10 | N8: 10 | O8: 10 | P8: 10 | Q8: 10
I9: 10 | J9: 80 | M9: 10 | N9: 10 | O9: 10 | P9: 10 | Q9: 10
I10: 10 | J10: 90 | M10: 10 | N10: 10 | O10: 10 | P10: 10 | Q10: 10
I11: 10 | J11: 100 | M11: 10 | N11: 10 | O11: 10 | P11: 10 | Q11: 10
I12: 10 | J12: 110
F16: Mon | I16: tulip | K16: Apple
F17: Tue | I17: rose | K17: Orange
F18: Wed | I18: hibiscus | K18: Pineapple
F19: Thu | I19: mogra | K19: Mango
F20: Fri | I20: tulip
F21: Sat
F22: Sun

Sheet Flash_Fill
A1: Reg. Number | B1: First 3 digits | E1: Reg. Number | F1: Last 3 digits | H1: Name | I1: Capital | K1: Name | L1: UPPER | N1: First Name | O1: Last Name | P1: Full Name | Q1: Full Name 2
A2: 101-A23-123 | B2: 101 | E2: 101-A23-101 | F2: 101 | H2: Nisha | I2: NISHA | K2: Nisha | L2: =UPPER(K2) -> NISHA | N2: Nisha | O2: Roy | P2: Nisha Roy | Q2: =_xlfn.CONCAT(N2," ",O2) -> Nisha Roy
A3: 109-B34-543 | B3: 109 | E3: 109-B34-543 | F3: 543 | H3: Amrita | I3: AMRITA | K3: Amrita | L3: =UPPER(K3) -> AMRITA | N3: Amrita | O3: Das | P3: Amrita Das | Q3: =_xlfn.CONCAT(N3," ",O3) -> Amrita Das
A4: 345-556-343 | B4: 345 | E4: 345-556-343 | F4: 343 | H4: Arnab | I4: ARNAB | K4: Arnab | L4: =UPPER(K4) -> ARNAB | N4: Arnab | O4: Sahu | P4: Arnab Sahu | Q4: =_xlfn.CONCAT(N4," ",O4) -> Arnab Sahu
A5: 564-R12-512 | B5: 564 | E5: 564-R12-512 | F5: 512 | H5: Ashis | I5: ASHIS | K5: Ashis | L5: =UPPER(K5) -> ASHIS | N5: Ashis | O5: Pal | P5: Ashis Pal | Q5: =_xlfn.CONCAT(N5," ",O5) -> Ashis Pal

Sheet E_Commerce_Formulas
A1: Order ID | B1: Customer ID | C1: Order Date | D1: Ship Date | E1: City | F1: State | G1: Sales Channel | H1: Payment Method | I1: Product Category | J1: Product Name | K1: Brand | L1: Units Sold | M1: Unit Price | N1: Total Price | O1: Discount % | P1: Discount Amount | Q1: Price after discount | R1: Sale Status | S1: Sale Status1 | T1: Sale Status2
A2: 10001 | B2: 1102 | C2: 45197 | D2: 45203 | E2: Chennai | F2: Delhi | G2: Mobile App | H2: Credit Card | I2: Home & Kitchen | J2: Mixer Grinder | K2: BrandA | L2: 7 | M2: 2843.87 | N2: =L2*M2 -> 19907.09 | O2: 0 | P2: =N2*O2% -> 0 | Q2: =N2-P2 -> 19907.09 | R2: =IF(L2>=5,"High Sale", "Low Sale") -> High Sale | S2: {=_xlfn.IFS(L2>5,"High",L2=5,"Medium",L2<5,"Low")} -> High | T2: =IF(L2>5,"High",IF(L2=5,"Medium","Low")) -> High
A3: 10002 | B3: 1435 | C3: 45199 | D3: 45203 | E3: Pune | F3: Tamil Nadu | G3: Website | H3: Debit Card | I3: Sports | J3: Football | K3: BrandD | L3: 9 | M3: 2525.23 | N3: =L3*M3 -> 22727.07 | O3: 5 | P3: =N3*O3% -> 1136.3535 | Q3: =N3-P3 -> 21590.716 | R3: =IF(L3>=5,"High Sale", "Low Sale") -> High Sale | S3: {=_xlfn.IFS(L3>5,"High",L3=5,"Medium",L3<5,"Low")} -> High | T3: =IF(L3>5,"High",IF(L3=5,"Medium","Low")) -> High | V3: No. of Customers: | W3: =COUNT(A2:A373) -> 372 | AB3: BrandA | AC3: 1 | AF3: Sports
A4: 10003 | B4: 1860 | C4: 45109 | D4: 45114 | E4: Chennai | F4: West Bengal | G4: Marketplace | H4: Debit Card | I4: Fashion | J4: Sneakers | K4: BrandE | L4: 6 | M4: 3474.34 | N4: =L4*M4 -> 20846.04 | O4: 15 | P4: =N4*O4% -> 3126.906 | Q4: =N4-P4 -> 17719.134 | R4: =IF(L4>=5,"High Sale", "Low Sale") -> High Sale | S4: {=_xlfn.IFS(L4>5,"High",L4=5,"Medium",L4<5,"Low")} -> High | T4: =IF(L4>5,"High",IF(L4=5,"Medium","Low")) -> High | V4: Units sold >5 | W4: =COUNTIF(L2:L373,">5") -> 169 | AB4: BrandD | AC4: 2 | AF4: Fashion
A5: 10004 | B5: 1270 | C5: 45079 | D5: 45087 | E5: Bengaluru | F5: West Bengal | G5: Website | H5: Cash on Delivery | I5: Sports | J5: Yoga Mat | K5: BrandA | L5: 1 | M5: 1008.79 | N5: =L5*M5 -> 1008.79 | O5: 15 | P5: =N5*O5% -> 151.3185 | Q5: =N5-P5 -> 857.4715 | R5: =IF(L5>=5,"High Sale", "Low Sale") -> Low Sale | S5: {=_xlfn.IFS(L5>5,"High",L5=5,"Medium",L5<5,"Low")} -> Low | T5: =IF(L5>5,"High",IF(L5=5,"Medium","Low")) -> Low | V5: Units sold >5 and Brand=BrandA: | W5: =COUNTIFS(K2:K373,"BrandA",L2:L373,">5") -> 35 | AB5: BrandE | AC5: 3 | AF5: Home & Kitchen
A6: 10005 | B6: 1106 | C6: 45241 | D6: 45244 | E6: Kolkata | F6: Karnataka | G6: Marketplace | H6: Credit Card | I6: Fashion | J6: Jacket | K6: BrandA | L6: 7 | M6: 3511.47 | N6: =L6*M6 -> 24580.29 | O6: 20 | P6: =N6*O6% -> 4916.058 | Q6: =N6-P6 -> 19664.232 | R6: =IF(L6>=5,"High Sale", "Low Sale") -> High Sale | S6: {=_xlfn.IFS(L6>5,"High",L6=5,"Medium",L6<5,"Low")} -> High | T6: =IF(L6>5,"High",IF(L6=5,"Medium","Low")) -> High | AB6: BrandC | AC6: 4 | AF6: Electronics
A7: 10006 | B7: 1071 | C7: 45260 | D7: 45263 | E7: Hyderabad | F7: Telangana | G7: Website | H7: Net Banking | I7: Home & Kitchen | J7: Bedsheet | K7: BrandE | L7: 3 | M7: 3189.55 | N7: =L7*M7 -> 9568.65 | O7: 10 | P7: =N7*O7% -> 956.865 | Q7: =N7-P7 -> 8611.785 | R7: =IF(L7>=5,"High Sale", "Low Sale") -> Low Sale | S7: {=_xlfn.IFS(L7>5,"High",L7=5,"Medium",L7<5,"Low")} -> Low | T7: =IF(L7>5,"High",IF(L7=5,"Medium","Low")) -> Low | V7: Brand | W7: Units sold greater than | X7: Number | AB7: BrandB | AC7: 5 | AF7: Beauty
A8: 10007 | B8: 1700 | C8: 45050 | D8: 45054 | E8: Bengaluru | F8: Telangana | G8: Mobile App | H8: UPI | I8: Fashion | J8: Sneakers | K8: BrandC | L8: 5 | M8: 3030.42 | N8: =L8*M8 -> 15152.1 | O8: 10 | P8: =N8*O8% -> 1515.21 | Q8: =N8-P8 -> 13636.89 | R8: =IF(L8>=5,"High Sale", "Low Sale") -> High Sale | S8: {=_xlfn.IFS(L8>5,"High",L8=5,"Medium",L8<5,"Low")} -> Medium | T8: =IF(L8>5,"High",IF(L8=5,"Medium","Low")) -> Medium | V8: BrandC | W8: 4 | X8: =COUNTIFS(K2:K373,V8,L2:L373,">="&W8) -> 51 | AC8: 6 | AF8: Books
A9: 10008 | B9: 1020 | C9: 45040 | D9: 45041 | E9: Mumbai | F9: Delhi | G9: Website | H9: Credit Card | I9: Fashion | J9: Sneakers | K9: BrandB | L9: 4 | M9: 2310.83 | N9: =L9*M9 -> 9243.32 | O9: 10 | P9: =N9*O9% -> 924.332 | Q9: =N9-P9 -> 8318.988 | R9: =IF(L9>=5,"High Sale", "Low Sale") -> Low Sale | S9: {=_xlfn.IFS(L9>5,"High",L9=5,"Medium",L9<5,"Low")} -> Low | T9: =IF(L9>5,"High",IF(L9=5,"Medium","Low")) -> Low | AC9: 7
A10: 10009 | B10: 1614 | C10: 45204 | D10: 45213 | E10: Chennai | F10: West Bengal | G10: Website | H10: Debit Card | I10: Fashion | J10: T-Shirt | K10: BrandD | L10: 5 | M10: 1098.04 | N10: =L10*M10 -> 5490.2 | O10: 15 | P10: =N10*O10% -> 823.53 | Q10: =N10-P10 -> 4666.67 | R10: =IF(L10>=5,"High Sale", "Low Sale") -> High Sale | S10: {=_xlfn.IFS(L10>5,"High",L10=5,"Medium",L10<5,"Low")} -> Medium | T10: =IF(L10>5,"High",IF(L10=5,"Medium","Low")) -> Medium | V10: Total Revenue (Price After Discount) | W10: =SUM(Q2:Q373) -> 3286225.2 | AC10: 8
A11: 10010 | B11: 1121 | C11: 45139 | D11: 45147 | E11: Bengaluru | F11: Karnataka | G11: Website | H11: Cash on Delivery | I11: Electronics | J11: Headphones | K11: BrandB | L11: 5 | M11: 1780.66 | N11: =L11*M11 -> 8903.3 | O11: 20 | P11: =N11*O11% -> 1780.66 | Q11: =N11-P11 -> 7122.64 | R11: =IF(L11>=5,"High Sale", "Low Sale") -> High Sale | S11: {=_xlfn.IFS(L11>5,"High",L11=5,"Medium",L11<5,"Low")} -> Medium | T11: =IF(L11>5,"High",IF(L11=5,"Medium","Low")) -> Medium | AC11: 9
A12: 10011 | B12: 1466 | C12: 45098 | D12: 45106 | E12: Bengaluru | F12: Karnataka | G12: Mobile App | H12: Cash on Delivery | I12: Electronics | J12: Headphones | K12: BrandE | L12: 6 | M12: 3205.25 | N12: =L12*M12 -> 19231.5 | O12: 0 | P12: =N12*O12% -> 0 | Q12: =N12-P12 -> 19231.5 | R12: =IF(L12>=5,"High Sale", "Low Sale") -> High Sale | S12: {=_xlfn.IFS(L12>5,"High",L12=5,"Medium",L12<5,"Low")} -> High | T12: =IF(L12>5,"High",IF(L12=5,"Medium","Low")) -> High | V12: Brand | W12: Total units sold | AC12: 10
A13: 10012 | B13: 1214 | C13: 45214 | D13: 45220 | E13: Mumbai | F13: Tamil Nadu | G13: Website | H13: UPI | I13: Electronics | J13: Smartwatch | K13: BrandA | L13: 6 | M13: 272.35 | N13: =L13*M13 -> 1634.1 | O13: 5 | P13: =N13*O13% -> 81.705 | Q13: =N13-P13 -> 1552.395 | R13: =IF(L13>=5,"High Sale", "Low Sale") -> High Sale | S13: {=_xlfn.IFS(L13>5,"High",L13=5,"Medium",L13<5,"Low")} -> High | T13: =IF(L13>5,"High",IF(L13=5,"Medium","Low")) -> High | V13: BrandE | W13: =SUMIF(K2:K373,V13,L2:L373) -> 425 | AC13: 11
A14: 10013 | B14: 1330 | C14: 45100 | D14: 45107 | E14: Delhi | F14: Tamil Nadu | G14: Mobile App | H14: Cash on Delivery | I14: Home & Kitchen | J14: Bedsheet | K14: BrandA | L14: 8 | M14: 3160.9 | N14: =L14*M14 -> 25287.2 | O14: 0 | P14: =N14*O14% -> 0 | Q14: =N14-P14 -> 25287.2 | R14: =IF(L14>=5,"High Sale", "Low Sale") -> High Sale | S14: {=_xlfn.IFS(L14>5,"High",L14=5,"Medium",L14<5,"Low")} -> High | T14: =IF(L14>5,"High",IF(L14=5,"Medium","Low")) -> High | AC14: 12
A15: 10014 | B15: 1458 | C15: 45039 | D15: 45045 | E15: Kolkata | F15: Karnataka | G15: Marketplace | H15: Cash on Delivery | I15: Sports | J15: Yoga Mat | K15: BrandD | L15: 8 | M15: 1074.27 | N15: =L15*M15 -> 8594.16 | O15: 15 | P15: =N15*O15% -> 1289.124 | Q15: =N15-P15 -> 7305.036 | R15: =IF(L15>=5,"High Sale", "Low Sale") -> High Sale | S15: {=_xlfn.IFS(L15>5,"High",L15=5,"Medium",L15<5,"Low")} -> High | T15: =IF(L15>5,"High",IF(L15=5,"Medium","Low")) -> High | V15: Product Category | W15: Brand | X15: Total units sold | AC15: 13
A16: 10015 | B16: 1087 | C16: 45048 | D16: 45057 | E16: Hyderabad | F16: Tamil Nadu | G16: Website | H16: Credit Card | I16: Beauty | J16: Shampoo | K16: BrandA | L16: 9 | M16: 705.59 | N16: =L16*M16 -> 6350.31 | O16: 10 | P16: =N16*O16% -> 635.031 | Q16: =N16-P16 -> 5715.279 | R16: =IF(L16>=5,"High Sale", "Low Sale") -> High Sale | S16: {=_xlfn.IFS(L16>5,"High",L16=5,"Medium",L16<5,"Low")} -> High | T16: =IF(L16>5,"High",IF(L16=5,"Medium","Low")) -> High | V16: Home & Kitchen | W16: BrandA | X16: =SUMIFS(L2:L373,I2:I373,V16,K2:K373,W16) -> 39 | AC16: 14
A17: 10016 | B17: 1372 | C17: 44958 | D17: 44961 | E17: Pune | F17: West Bengal | G17: Mobile App | H17: Net Banking | I17: Fashion | J17: Jacket | K17: BrandA | L17: 8 | M17: 595.45 | N17: =L17*M17 -> 4763.6 | O17: 5 | P17: =N17*O17% -> 238.18 | Q17: =N17-P17 -> 4525.42 | R17: =IF(L17>=5,"High Sale", "Low Sale") -> High Sale | S17: {=_xlfn.IFS(L17>5,"High",L17=5,"Medium",L17<5,"Low")} -> High | T17: =IF(L17>5,"High",IF(L17=5,"Medium","Low")) -> High | AC17: 15
A18: 10017 | B18: 1099 | C18: 45148 | D18: 45151 | E18: Delhi | F18: Maharashtra | G18: Mobile App | H18: UPI | I18: Fashion | J18: Jacket | K18: BrandD | L18: 2 | M18: 254.91 | N18: =L18*M18 -> 509.82 | O18: 15 | P18: =N18*O18% -> 76.473 | Q18: =N18-P18 -> 433.347 | R18: =IF(L18>=5,"High Sale", "Low Sale") -> Low Sale | S18: {=_xlfn.IFS(L18>5,"High",L18=5,"Medium",L18<5,"Low")} -> Low | T18: =IF(L18>5,"High",IF(L18=5,"Medium","Low")) -> Low | V18: Total Revenue1 (Total Price) | W18: =SUM(N2:N373) -> 3664518.5 | AC18: 16
A19: 10018 | B19: 1871 | C19: 45045 | D19: 45048 | E19: Chennai | F19: West Bengal | G19: Website | H19: Credit Card | I19: Home & Kitchen | J19: Curtains | K19: BrandD | L19: 1 | M19: 2165.81 | N19: =L19*M19 -> 2165.81 | O19: 15 | P19: =N19*O19% -> 324.8715 | Q19: =N19-P19 -> 1840.9385 | R19: =IF(L19>=5,"High Sale", "Low Sale") -> Low Sale | S19: {=_xlfn.IFS(L19>5,"High",L19=5,"Medium",L19<5,"Low")} -> Low | T19: =IF(L19>5,"High",IF(L19=5,"Medium","Low")) -> Low
A20: 10019 | B20: 1663 | C20: 44965 | D20: 44968 | E20: Bengaluru | F20: Karnataka | G20: Marketplace | H20: Net Banking | I20: Fashion | J20: Jacket | K20: BrandE | L20: 2 | M20: 990.3 | N20: =L20*M20 -> 1980.6 | O20: 15 | P20: =N20*O20% -> 297.09 | Q20: =N20-P20 -> 1683.51 | R20: =IF(L20>=5,"High Sale", "Low Sale") -> Low Sale | S20: {=_xlfn.IFS(L20>5,"High",L20=5,"Medium",L20<5,"Low")} -> Low | T20: =IF(L20>5,"High",IF(L20=5,"Medium","Low")) -> Low | V20: Total Revenue2 (Total Price) | W20: =SUMPRODUCT(L2:L373,M2:M373) -> 3664518.5
A21: 10020 | B21: 1130 | C21: 45194 | D21: 45203 | E21: Mumbai | F21: Karnataka | G21: Mobile App | H21: Credit Card | I21: Electronics | J21: Smartwatch | K21: BrandA | L21: 2 | M21: 3959.31 | N21: =L21*M21 -> 7918.62 | O21: 5 | P21: =N21*O21% -> 395.931 | Q21: =N21-P21 -> 7522.689 | R21: =IF(L21>=5,"High Sale", "Low Sale") -> Low Sale | S21: {=_xlfn.IFS(L21>5,"High",L21=5,"Medium",L21<5,"Low")} -> Low | T21: =IF(L21>5,"High",IF(L21=5,"Medium","Low")) -> Low
A22: 10021 | B22: 1661 | C22: 45159 | D22: 45163 | E22: Mumbai | F22: West Bengal | G22: Website | H22: Credit Card | I22: Beauty | J22: Lipstick | K22: BrandA | L22: 3 | M22: 2361.58 | N22: =L22*M22 -> 7084.74 | O22: 5 | P22: =N22*O22% -> 354.237 | Q22: =N22-P22 -> 6730.503 | R22: =IF(L22>=5,"High Sale", "Low Sale") -> Low Sale | S22: {=_xlfn.IFS(L22>5,"High",L22=5,"Medium",L22<5,"Low")} -> Low | T22: =IF(L22>5,"High",IF(L22=5,"Medium","Low")) -> Low | V22: Brand | W22: Total Revenue
A23: 10022 | B23: 1308 | C23: 44944 | D23: 44951 | E23: Kolkata | F23: Tamil Nadu | G23: Marketplace | H23: Cash on Delivery | I23: Books | J23: Fiction Novel | K23: BrandE | L23: 7 | M23: 680.86 | N23: =L23*M23 -> 4766.02 | O23: 20 | P23: =N23*O23% -> 953.204 | Q23: =N23-P23 -> 3812.816 | R23: =IF(L23>=5,"High Sale", "Low Sale") -> High Sale | S23: {=_xlfn.IFS(L23>5,"High",L23=5,"Medium",L23<5,"Low")} -> High | T23: =IF(L23>5,"High",IF(L23=5,"Medium","Low")) -> High | V23: BrandA | W23: {=SUMPRODUCT(L2:L373,M2:M373,--(K2:K373=V23))} -> 737855.54
A24: 10023 | B24: 1769 | C24: 45075 | D24: 45084 | E24: Delhi | F24: Tamil Nadu | G24: Mobile App | H24: Net Banking | I24: Fashion | J24: Sneakers | K24: BrandC | L24: 2 | M24: 2801.74 | N24: =L24*M24 -> 5603.48 | O24: 20 | P24: =N24*O24% -> 1120.696 | Q24: =N24-P24 -> 4482.784 | R24: =IF(L24>=5,"High Sale", "Low Sale") -> Low Sale | S24: {=_xlfn.IFS(L24>5,"High",L24=5,"Medium",L24<5,"Low")} -> Low | T24: =IF(L24>5,"High",IF(L24=5,"Medium","Low")) -> Low
A25: 10024 | B25: 1343 | C25: 45075 | D25: 45082 | E25: Pune | F25: Telangana | G25: Mobile App | H25: UPI | I25: Electronics | J25: Smartwatch | K25: BrandC | L25: 1 | M25: 3606.31 | N25: =L25*M25 -> 3606.31 | O25: 0 | P25: =N25*O25% -> 0 | Q25: =N25-P25 -> 3606.31 | R25: =IF(L25>=5,"High Sale", "Low Sale") -> Low Sale | S25: {=_xlfn.IFS(L25>5,"High",L25=5,"Medium",L25<5,"Low")} -> Low | T25: =IF(L25>5,"High",IF(L25=5,"Medium","Low")) -> Low | V25: Average total price of items | W25: =AVERAGE(N2:N373) -> 9850.8563
A26: 10025 | B26: 1491 | C26: 45052 | D26: 45061 | E26: Kolkata | F26: Karnataka | G26: Marketplace | H26: UPI | I26: Books | J26: Comics | K26: BrandC | L26: 6 | M26: 3018.94 | N26: =L26*M26 -> 18113.64 | O26: 5 | P26: =N26*O26% -> 905.682 | Q26: =N26-P26 -> 17207.958 | R26: =IF(L26>=5,"High Sale", "Low Sale") -> High Sale | S26: {=_xlfn.IFS(L26>5,"High",L26=5,"Medium",L26<5,"Low")} -> High | T26: =IF(L26>5,"High",IF(L26=5,"Medium","Low")) -> High
A27: 10026 | B27: 1413 | C27: 45228 | D27: 45231 | E27: Bengaluru | F27: Delhi | G27: Marketplace | H27: Net Banking | I27: Beauty | J27: Perfume | K27: BrandE | L27: 9 | M27: 444.29 | N27: =L27*M27 -> 3998.61 | O27: 5 | P27: =N27*O27% -> 199.9305 | Q27: =N27-P27 -> 3798.6795 | R27: =IF(L27>=5,"High Sale", "Low Sale") -> High Sale | S27: {=_xlfn.IFS(L27>5,"High",L27=5,"Medium",L27<5,"Low")} -> High | T27: =IF(L27>5,"High",IF(L27=5,"Medium","Low")) -> High | V27: Brand | W27: Average unit sold
A28: 10027 | B28: 1805 | C28: 45286 | D28: 45290 | E28: Kolkata | F28: Telangana | G28: Website | H28: Cash on Delivery | I28: Books | J28: Fiction Novel | K28: BrandA | L28: 3 | M28: 3599.15 | N28: =L28*M28 -> 10797.45 | O28: 5 | P28: =N28*O28% -> 539.8725 | Q28: =N28-P28 -> 10257.578 | R28: =IF(L28>=5,"High Sale", "Low Sale") -> Low Sale | S28: {=_xlfn.IFS(L28>5,"High",L28=5,"Medium",L28<5,"Low")} -> Low | T28: =IF(L28>5,"High",IF(L28=5,"Medium","Low")) -> Low | V28: BrandE | W28: =AVERAGEIF(K2:K373,V28,L2:L373) -> 5.1204819
A29: 10028 | B29: 1385 | C29: 45164 | D29: 45172 | E29: Hyderabad | F29: Tamil Nadu | G29: Website | H29: Debit Card | I29: Electronics | J29: Smartwatch | K29: BrandE | L29: 6 | M29: 3206.63 | N29: =L29*M29 -> 19239.78 | O29: 20 | P29: =N29*O29% -> 3847.956 | Q29: =N29-P29 -> 15391.824 | R29: =IF(L29>=5,"High Sale", "Low Sale") -> High Sale | S29: {=_xlfn.IFS(L29>5,"High",L29=5,"Medium",L29<5,"Low")} -> High | T29: =IF(L29>5,"High",IF(L29=5,"Medium","Low")) -> High
A30: 10029 | B30: 1191 | C30: 45061 | D30: 45067 | E30: Mumbai | F30: West Bengal | G30: Mobile App | H30: Credit Card | I30: Sports | J30: Football | K30: BrandE | L30: 3 | M30: 759.47 | N30: =L30*M30 -> 2278.41 | O30: 15 | P30: =N30*O30% -> 341.7615 | Q30: =N30-P30 -> 1936.6485 | R30: =IF(L30>=5,"High Sale", "Low Sale") -> Low Sale | S30: {=_xlfn.IFS(L30>5,"High",L30=5,"Medium",L30<5,"Low")} -> Low | T30: =IF(L30>5,"High",IF(L30=5,"Medium","Low")) -> Low | V30: Product Category | W30: Brand | X30: Average units sold
A31: 10030 | B31: 1955 | C31: 45077 | D31: 45082 | E31: Mumbai | F31: Tamil Nadu | G31: Marketplace | H31: Cash on Delivery | I31: Sports | J31: Cricket Bat | K31: BrandC | L31: 1 | M31: 349.38 | N31: =L31*M31 -> 349.38 | O31: 10 | P31: =N31*O31% -> 34.938 | Q31: =N31-P31 -> 314.442 | R31: =IF(L31>=5,"High Sale", "Low Sale") -> Low Sale | S31: {=_xlfn.IFS(L31>5,"High",L31=5,"Medium",L31<5,"Low")} -> Low | T31: =IF(L31>5,"High",IF(L31=5,"Medium","Low")) -> Low | V31: Home & Kitchen | W31: BrandA | X31: =AVERAGEIFS(L2:L373,I2:I373,V31,K2:K373,W31) -> 6.5
A32: 10031 | B32: 1276 | C32: 45162 | D32: 45166 | E32: Chennai | F32: West Bengal | G32: Marketplace | H32: Net Banking | I32: Books | J32: Textbook | K32: BrandB | L32: 5 | M32: 2295.65 | N32: =L32*M32 -> 11478.25 | O32: 20 | P32: =N32*O32% -> 2295.65 | Q32: =N32-P32 -> 9182.6 | R32: =IF(L32>=5,"High Sale", "Low Sale") -> High Sale | S32: {=_xlfn.IFS(L32>5,"High",L32=5,"Medium",L32<5,"Low")} -> Medium | T32: =IF(L32>5,"High",IF(L32=5,"Medium","Low")) -> Medium
A33: 10032 | B33: 1160 | C33: 45150 | D33: 45158 | E33: Chennai | F33: Telangana | G33: Marketplace | H33: Credit Card | I33: Home & Kitchen | J33: Bedsheet | K33: BrandA | L33: 4 | M33: 750.74 | N33: =L33*M33 -> 3002.96 | O33: 5 | P33: =N33*O33% -> 150.148 | Q33: =N33-P33 -> 2852.812 | R33: =IF(L33>=5,"High Sale", "Low Sale") -> Low Sale | S33: {=_xlfn.IFS(L33>5,"High",L33=5,"Medium",L33<5,"Low")} -> Low | T33: =IF(L33>5,"High",IF(L33=5,"Medium","Low")) -> Low
A34: 10033 | B34: 1459 | C34: 45129 | D34: 45130 | E34: Pune | F34: Karnataka | G34: Mobile App | H34: UPI | I34: Books | J34: Comics | K34: BrandC | L34: 7 | M34: 3363.18 | N34: =L34*M34 -> 23542.26 | O34: 20 | P34: =N34*O34% -> 4708.452 | Q34: =N34-P34 -> 18833.808 | R34: =IF(L34>=5,"High Sale", "Low Sale") -> High Sale | S34: {=_xlfn.IFS(L34>5,"High",L34=5,"Medium",L34<5,"Low")} -> High | T34: =IF(L34>5,"High",IF(L34=5,"Medium","Low")) -> High
A35: 10034 | B35: 1313 | C35: 45182 | D35: 45191 | E35: Bengaluru | F35: Tamil Nadu | G35: Marketplace | H35: Debit Card | I35: Fashion | J35: T-Shirt | K35: BrandB | L35: 6 | M35: 1529.59 | N35: =L35*M35 -> 9177.54 | O35: 0 | P35: =N35*O35% -> 0 | Q35: =N35-P35 -> 9177.54 | R35: =IF(L35>=5,"High Sale", "Low Sale") -> High Sale | S35: {=_xlfn.IFS(L35>5,"High",L35=5,"Medium",L35<5,"Low")} -> High | T35: =IF(L35>5,"High",IF(L35=5,"Medium","Low")) -> High
A36: 10035 | B36: 1021 | C36: 45012 | D36: 45013 | E36: Hyderabad | F36: West Bengal | G36: Marketplace | H36: UPI | I36: Fashion | J36: T-Shirt | K36: BrandB | L36: 7 | M36: 3664.64 | N36: =L36*M36 -> 25652.48 | O36: 5 | P36: =N36*O36% -> 1282.624 | Q36: =N36-P36 -> 24369.856 | R36: =IF(L36>=5,"High Sale", "Low Sale") -> High Sale | S36: {=_xlfn.IFS(L36>5,"High",L36=5,"Medium",L36<5,"Low")} -> High | T36: =IF(L36>5,"High",IF(L36=5,"Medium","Low")) -> High
A37: 10036 | B37: 1252 | C37: 45076 | D37: 45084 | E37: Delhi | F37: Karnataka | G37: Mobile App | H37: Net Banking | I37: Sports | J37: Football | K37: BrandD | L37: 5 | M37: 2327.9 | N37: =L37*M37 -> 11639.5 | O37: 0 | P37: =N37*O37% -> 0 | Q37: =N37-P37 -> 11639.5 | R37: =IF(L37>=5,"High Sale", "Low Sale") -> High Sale | S37: {=_xlfn.IFS(L37>5,"High",L37=5,"Medium",L37<5,"Low")} -> Medium | T37: =IF(L37>5,"High",IF(L37=5,"Medium","Low")) -> Medium
A38: 10037 | B38: 1747 | C38: 45161 | D38: 45165 | E38: Kolkata | F38: Delhi | G38: Website | H38: Credit Card | I38: Home & Kitchen | J38: Curtains | K38: BrandA | L38: 4 | M38: 853.29 | N38: =L38*M38 -> 3413.16 | O38: 5 | P38: =N38*O38% -> 170.658 | Q38: =N38-P38 -> 3242.502 | R38: =IF(L38>=5,"High Sale", "Low Sale") -> Low Sale | S38: {=_xlfn.IFS(L38>5,"High",L38=5,"Medium",L38<5,"Low")} -> Low | T38: =IF(L38>5,"High",IF(L38=5,"Medium","Low")) -> Low
A39: 10038 | B39: 1856 | C39: 45271 | D39: 45280 | E39: Pune | F39: West Bengal | G39: Website | H39: Net Banking | I39: Electronics | J39: Laptop | K39: BrandB | L39: 7 | M39: 687.46 | N39: =L39*M39 -> 4812.22 | O39: 20 | P39: =N39*O39% -> 962.444 | Q39: =N39-P39 -> 3849.776 | R39: =IF(L39>=5,"High Sale", "Low Sale") -> High Sale | S39: {=_xlfn.IFS(L39>5,"High",L39=5,"Medium",L39<5,"Low")} -> High | T39: =IF(L39>5,"High",IF(L39=5,"Medium","Low")) -> High
A40: 10039 | B40: 1560 | C40: 44948 | D40: 44953 | E40: Bengaluru | F40: Telangana | G40: Mobile App | H40: Credit Card | I40: Fashion | J40: T-Shirt | K40: BrandC | L40: 7 | M40: 2369.42 | N40: =L40*M40 -> 16585.94 | O40: 15 | P40: =N40*O40% -> 2487.891 | Q40: =N40-P40 -> 14098.049 | R40: =IF(L40>=5,"High Sale", "Low Sale") -> High Sale | S40: {=_xlfn.IFS(L40>5,"High",L40=5,"Medium",L40<5,"Low")} -> High | T40: =IF(L40>5,"High",IF(L40=5,"Medium","Low")) -> High
...

Sheet E_Commerce_Sort_Filter
A1: Order ID | B1: Customer ID | C1: Order Date | D1: Ship Date | E1: City | F1: State | G1: Sales Channel | H1: Payment Method | I1: Product Category | J1: Product Name | K1: Brand | L1: Units Sold | M1: Unit Price | N1: Discount %
A2: 10026 | B2: 1413 | C2: 45228 | D2: 45231 | E2: Bengaluru | F2: Delhi | G2: Marketplace | H2: Net Banking | I2: Beauty | J2: Perfume | K2: BrandE | L2: 9 | M2: 444.29 | N2: 5
A3: 10454 | B3: 1959 | C3: 45251 | D3: 45255 | E3: Bengaluru | F3: Telangana | G3: Mobile App | H3: Debit Card | I3: Books | J3: Fiction Novel | K3: BrandD | L3: 9 | M3: 3191.56 | N3: 20
A4: 10238 | B4: 1224 | C4: 45089 | D4: 45093 | E4: Bengaluru | F4: Karnataka | G4: Website | H4: Cash on Delivery | I4: Books | J4: Textbook | K4: BrandC | L4: 8 | M4: 284.52 | N4: 15 | P4: City | Q4: Payment Method
A5: 10360 | B5: 1610 | C5: 45123 | D5: 45124 | E5: Bengaluru | F5: Telangana | G5: Marketplace | H5: Net Banking | I5: Fashion | J5: Sneakers | K5: BrandC | L5: 8 | M5: 1392.5 | N5: 15 | P5: Chennai | Q5: Net Banking
A6: 10470 | B6: 1045 | C6: 44927 | D6: 44936 | E6: Bengaluru | F6: West Bengal | G6: Marketplace | H6: Credit Card | I6: Sports | J6: Yoga Mat | K6: BrandD | L6: 8 | M6: 150.72 | N6: 5
A7: 10481 | B7: 1180 | C7: 44947 | D7: 44955 | E7: Bengaluru | F7: Telangana | G7: Mobile App | H7: UPI | I7: Electronics | J7: Headphones | K7: BrandB | L7: 8 | M7: 1160.51 | N7: 0 | P7: Order ID | Q7: Customer ID | R7: Order Date | S7: Ship Date | T7: City | U7: State | V7: Sales Channel | W7: Payment Method | X7: Product Category | Y7: Product Name | Z7: Brand | AA7: Units Sold | AB7: Unit Price | AC7: Discount %
A8: 10489 | B8: 1980 | C8: 45178 | D8: 45187 | E8: Bengaluru | F8: Tamil Nadu | G8: Website | H8: Credit Card | I8: Books | J8: Textbook | K8: BrandE | L8: 8 | M8: 2536.88 | N8: 5 | P8: 10001 | Q8: 1102 | R8: 45197 | S8: 45203 | T8: Chennai | U8: Delhi | V8: Mobile App | W8: Credit Card | X8: Home & Kitchen | Y8: Mixer Grinder | Z8: BrandA | AA8: 7 | AB8: 2843.87 | AC8: 0
A9: 10039 | B9: 1560 | C9: 44948 | D9: 44953 | E9: Bengaluru | F9: Telangana | G9: Mobile App | H9: Credit Card | I9: Fashion | J9: T-Shirt | K9: BrandC | L9: 7 | M9: 2369.42 | N9: 15 | P9: 10003 | Q9: 1860 | R9: 45109 | S9: 45114 | T9: Chennai | U9: West Bengal | V9: Marketplace | W9: Debit Card | X9: Fashion | Y9: Sneakers | Z9: BrandE | AA9: 6 | AB9: 3474.34 | AC9: 15
A10: 10131 | B10: 1014 | C10: 45142 | D10: 45151 | E10: Bengaluru | F10: Karnataka | G10: Website | H10: UPI | I10: Fashion | J10: Sneakers | K10: BrandA | L10: 7 | M10: 1899.45 | N10: 15 | P10: 10009 | Q10: 1614 | R10: 45204 | S10: 45213 | T10: Chennai | U10: West Bengal | V10: Website | W10: Debit Card | X10: Fashion | Y10: T-Shirt | Z10: BrandD | AA10: 5 | AB10: 1098.04 | AC10: 15
A11: 10185 | B11: 1870 | C11: 45016 | D11: 45023 | E11: Bengaluru | F11: Delhi | G11: Mobile App | H11: Credit Card | I11: Fashion | J11: Jacket | K11: BrandB | L11: 7 | M11: 898.62 | N11: 0 | P11: 10018 | Q11: 1871 | R11: 45045 | S11: 45048 | T11: Chennai | U11: West Bengal | V11: Website | W11: Credit Card | X11: Home & Kitchen | Y11: Curtains | Z11: BrandD | AA11: 1 | AB11: 2165.81 | AC11: 15
A12: 10482 | B12: 1606 | C12: 45153 | D12: 45162 | E12: Bengaluru | F12: Maharashtra | G12: Website | H12: Debit Card | I12: Books | J12: Biography | K12: BrandE | L12: 7 | M12: 2172.24 | N12: 20 | P12: 10031 | Q12: 1276 | R12: 45162 | S12: 45166 | T12: Chennai | U12: West Bengal | V12: Marketplace | W12: Net Banking | X12: Books | Y12: Textbook | Z12: BrandB | AA12: 5 | AB12: 2295.65 | AC12: 20
A13: 10011 | B13: 1466 | C13: 45098 | D13: 45106 | E13: Bengaluru | F13: Karnataka | G13: Mobile App | H13: Cash on Delivery | I13: Electronics | J13: Headphones | K13: BrandE | L13: 6 | M13: 3205.25 | N13: 0 | P13: 10032 | Q13: 1160 | R13: 45150 | S13: 45158 | T13: Chennai | U13: Telangana | V13: Marketplace | W13: Credit Card | X13: Home & Kitchen | Y13: Bedsheet | Z13: BrandA | AA13: 4 | AB13: 750.74 | AC13: 5
A14: 10034 | B14: 1313 | C14: 45182 | D14: 45191 | E14: Bengaluru | F14: Tamil Nadu | G14: Marketplace | H14: Debit Card | I14: Fashion | J14: T-Shirt | K14: BrandB | L14: 6 | M14: 1529.59 | N14: 0 | P14: 10040 | Q14: 1474 | R14: 45274 | S14: 45277 | T14: Chennai | U14: Delhi | V14: Marketplace | W14: Cash on Delivery | X14: Sports | Y14: Football | Z14: BrandD | AA14: 6 | AB14: 3083.25 | AC14: 10
A15: 10068 | B15: 1315 | C15: 45062 | D15: 45064 | E15: Bengaluru | F15: Telangana | G15: Marketplace | H15: UPI | I15: Fashion | J15: T-Shirt | K15: BrandD | L15: 6 | M15: 1380.66 | N15: 0 | P15: 10042 | Q15: 1510 | R15: 45195 | S15: 45204 | T15: Chennai | U15: Maharashtra | V15: Website | W15: Cash on Delivery | X15: Sports | Y15: Football | Z15: BrandE | AA15: 4 | AB15: 1211.67 | AC15: 20
A16: 10159 | B16: 1929 | C16: 45109 | D16: 45113 | E16: Bengaluru | F16: Delhi | G16: Website | H16: Debit Card | I16: Electronics | J16: Smartphone | K16: BrandC | L16: 6 | M16: 3800.77 | N16: 0 | P16: 10065 | Q16: 1273 | R16: 45054 | S16: 45058 | T16: Chennai | U16: Karnataka | V16: Mobile App | W16: Net Banking | X16: Home & Kitchen | Y16: Bedsheet | Z16: BrandC | AA16: 2 | AB16: 2773.21 | AC16: 10
A17: 10195 | B17: 1574 | C17: 45044 | D17: 45045 | E17: Bengaluru | F17: Tamil Nadu | G17: Mobile App | H17: Cash on Delivery | I17: Fashion | J17: Jeans | K17: BrandB | L17: 6 | M17: 344.65 | N17: 10 | P17: 10066 | Q17: 1387 | R17: 45155 | S17: 45158 | T17: Chennai | U17: Tamil Nadu | V17: Mobile App | W17: Cash on Delivery | X17: Books | Y17: Biography | Z17: BrandC | AA17: 8 | AB17: 3769.71 | AC17: 5
A18: 10371 | B18: 1253 | C18: 44973 | D18: 44979 | E18: Bengaluru | F18: Telangana | G18: Mobile App | H18: Credit Card | I18: Electronics | J18: Smartphone | K18: BrandB | L18: 6 | M18: 2715.13 | N18: 20 | P18: 10069 | Q18: 1013 | R18: 45288 | S18: 45296 | T18: Chennai | U18: Tamil Nadu | V18: Mobile App | W18: UPI | X18: Books | Y18: Textbook | Z18: BrandE | AA18: 6 | AB18: 1836.98 | AC18: 5
A19: 10007 | B19: 1700 | C19: 45050 | D19: 45054 | E19: Bengaluru | F19: Telangana | G19: Mobile App | H19: UPI | I19: Fashion | J19: Sneakers | K19: BrandC | L19: 5 | M19: 3030.42 | N19: 10 | P19: 10071 | Q19: 1776 | R19: 45070 | S19: 45078 | T19: Chennai | U19: West Bengal | V19: Mobile App | W19: Credit Card | X19: Sports | Y19: Cricket Bat | Z19: BrandB | AA19: 3 | AB19: 3854.71 | AC19: 5
... A63: 10040 | B63: 1474 | C63: 45274 | D63: 45277 | E63: Chennai | F63: Delhi | G63: Marketplace | H63: Cash on Delivery | I63: Sports | J63: Football | K63: BrandD | L63: 6 | M63: 3083.25 | N63: 10 | P63: 10500 | Q63: 1569 | R63: 44972 | S63: 44977 | T63: Chennai | U63: Delhi | V63: Marketplace | W63: Net Banking | X63: Fashion | Y63: Jeans | Z63: BrandE | AA63: 1 | AB63: 2432.17 | AC63: 20
A64: 10069 | B64: 1013 | C64: 45288 | D64: 45296 | E64: Chennai | F64: Tamil Nadu | G64: Mobile App | H64: UPI | I64: Books | J64: Textbook | K64: BrandE | L64: 6 | M64: 1836.98 | N64: 5
A65: 10286 | B65: 1641 | C65: 45043 | D65: 45050 | E65: Chennai | F65: West Bengal | G65: Mobile App | H65: UPI | I65: Books | J65: Fiction Novel | K65: BrandD | L65: 6 | M65: 220.79 | N65: 5
A66: 10496 | B66: 1017 | C66: 45177 | D66: 45178 | E66: Chennai | F66: Tamil Nadu | G66: Mobile App | H66: Net Banking | I66: Beauty | J66: Perfume | K66: BrandC | L66: 6 | M66: 1128.91 | N66: 20
A67: 10009 | B67: 1614 | C67: 45204 | D67: 45213 | E67: Chennai | F67: West Bengal | G67: Website | H67: Debit Card | I67: Fashion | J67: T-Shirt | K67: BrandD | L67: 5 | M67: 1098.04 | N67: 15 | P67: Order ID | Q67: Customer ID | R67: Order Date | S67: Ship Date | T67: City | U67: State | V67: Sales Channel | W67: Payment Method | X67: Product Category | Y67: Product Name | Z67: Brand | AA67: Units Sold | AB67: Unit Price | AC67: Discount %
A68: 10031 | B68: 1276 | C68: 45162 | D68: 45166 | E68: Chennai | F68: West Bengal | G68: Marketplace | H68: Net Banking | I68: Books | J68: Textbook | K68: BrandB | L68: 5 | M68: 2295.65 | N68: 20 | P68: 10245 | Q68: 1972 | R68: 45143 | S68: 45148 | T68: Chennai | U68: Delhi | V68: Marketplace | W68: Net Banking | X68: Electronics | Y68: Smartwatch | Z68: BrandB | AA68: 8 | AB68: 1504.45 | AC68: 20
A69: 10181 | B69: 1217 | C69: 45050 | D69: 45053 | E69: Chennai | F69: Tamil Nadu | G69: Mobile App | H69: Net Banking | I69: Electronics | J69: Headphones | K69: BrandE | L69: 5 | M69: 2329.38 | N69: 20 | P69: 10496 | Q69: 1017 | R69: 45177 | S69: 45178 | T69: Chennai | U69: Tamil Nadu | V69: Mobile App | W69: Net Banking | X69: Beauty | Y69: Perfume | Z69: BrandC | AA69: 6 | AB69: 1128.91 | AC69: 20
A70: 10201 | B70: 1899 | C70: 44961 | D70: 44966 | E70: Chennai | F70: West Bengal | G70: Marketplace | H70: Net Banking | I70: Books | J70: Comics | K70: BrandD | L70: 5 | M70: 3501.94 | N70: 20 | P70: 10031 | Q70: 1276 | R70: 45162 | S70: 45166 | T70: Chennai | U70: West Bengal | V70: Marketplace | W70: Net Banking | X70: Books | Y70: Textbook | Z70: BrandB | AA70: 5 | AB70: 2295.65 | AC70: 20
A71: 10215 | B71: 1242 | C71: 45157 | D71: 45162 | E71: Chennai | F71: Delhi | G71: Mobile App | H71: Debit Card | I71: Sports | J71: Football | K71: BrandA | L71: 5 | M71: 633.43 | N71: 20 | P71: 10181 | Q71: 1217 | R71: 45050 | S71: 45053 | T71: Chennai | U71: Tamil Nadu | V71: Mobile App | W71: Net Banking | X71: Electronics | Y71: Headphones | Z71: BrandE | AA71: 5 | AB71: 2329.38 | AC71: 20
A72: 10269 | B72: 1829 | C72: 45125 | D72: 45132 | E72: Chennai | F72: Telangana | G72: Website | H72: Cash on Delivery | I72: Electronics | J72: Smartwatch | K72: BrandB | L72: 5 | M72: 3156.54 | N72: 20 | P72: 10201 | Q72: 1899 | R72: 44961 | S72: 44966 | T72: Chennai | U72: West Bengal | V72: Marketplace | W72: Net Banking | X72: Books | Y72: Comics | Z72: BrandD | AA72: 5 | AB72: 3501.94 | AC72: 20
A73: 10322 | B73: 1608 | C73: 45220 | D73: 45222 | E73: Chennai | F73: Maharashtra | G73: Marketplace | H73: Cash on Delivery | I73: Sports | J73: Cricket Bat | K73: BrandD | L73: 5 | M73: 640.82 | N73: 0 | P73: 10366 | Q73: 1571 | R73: 45223 | S73: 45226 | T73: Chennai | U73: Delhi | V73: Website | W73: Net Banking | X73: Electronics | Y73: Laptop | Z73: BrandA | AA73: 5 | AB73: 3320.88 | AC73: 0
A74: 10342 | B74: 1819 | C74: 45018 | D74: 45019 | E74: Chennai | F74: Maharashtra | G74: Mobile App | H74: Cash on Delivery | I74: Sports | J74: Football | K74: BrandB | L74: 5 | M74: 1853.11 | N74: 10 | P74: 10307 | Q74: 1183 | R74: 45267 | S74: 45273 | T74: Chennai | U74: Delhi | V74: Website | W74: Net Banking | X74: Books | Y74: Fiction Novel | Z74: BrandD | AA74: 4 | AB74: 2008.45 | AC74: 5
A75: 10366 | B75: 1571 | C75: 45223 | D75: 45226 | E75: Chennai | F75: Delhi | G75: Website | H75: Net Banking | I75: Electronics | J75: Laptop | K75: BrandA | L75: 5 | M75: 3320.88 | N75: 0 | P75: 10173 | Q75: 1960 | R75: 45124 | S75: 45127 | T75: Chennai | U75: Karnataka | V75: Website | W75: Net Banking | X75: Fashion | Y75: Jeans | Z75: BrandD | AA75: 3 | AB75: 1357.77 | AC75: 5
A76: 10472 | B76: 1517 | C76: 45269 | D76: 45278 | E76: Chennai | F76: Maharashtra | G76: Marketplace | H76: Cash on Delivery | I76: Fashion | J76: T-Shirt | K76: BrandD | L76: 5 | M76: 2523.25 | N76: 10 | P76: 10065 | Q76: 1273 | R76: 45054 | S76: 45058 | T76: Chennai | U76: Karnataka | V76: Mobile App | W76: Net Banking | X76: Home & Kitchen | Y76: Bedsheet | Z76: BrandC | AA76: 2 | AB76: 2773.21 | AC76: 10
A77: 10032 | B77: 1160 | C77: 45150 | D77: 45158 | E77: Chennai | F77: Telangana | G77: Marketplace | H77: Credit Card | I77: Home & Kitchen | J77: Bedsheet | K77: BrandA | L77: 4 | M77: 750.74 | N77: 5 | P77: 10332 | Q77: 1954 | R77: 44946 | S77: 44955 | T77: Chennai | U77: Tamil Nadu | V77: Mobile App | W77: Net Banking | X77: Books | Y77: Biography | Z77: BrandA | AA77: 2 | AB77: 1335.36 | AC77: 5
A78: 10042 | B78: 1510 | C78: 45195 | D78: 45204 | E78: Chennai | F78: Maharashtra | G78: Website | H78: Cash on Delivery | I78: Sports | J78: Football | K78: BrandE | L78: 4 | M78: 1211.67 | N78: 20 | P78: 10130 | Q78: 1156 | R78: 44929 | S78: 44938 | T78: Chennai | U78: Telangana | V78: Mobile App | W78: Net Banking | X78: Books | Y78: Textbook | Z78: BrandE | AA78: 1 | AB78: 2534.47 | AC78: 5
A79: 10264 | B79: 1607 | C79: 45086 | D79: 45091 | E79: Chennai | F79: Delhi | G79: Marketplace | H79: UPI | I79: Beauty | J79: Perfume | K79: BrandB | L79: 4 | M79: 1126.3 | N79: 20 | P79: 10500 | Q79: 1569 | R79: 44972 | S79: 44977 | T79: Chennai | U79: Delhi | V79: Marketplace | W79: Net Banking | X79: Fashion | Y79: Jeans | Z79: BrandE | AA79: 1 | AB79: 2432.17 | AC79: 20
A80: 10307 | B80: 1183 | C80: 45267 | D80: 45273 | E80: Chennai | F80: Delhi | G80: Website | H80: Net Banking | I80: Books | J80: Fiction Novel | K80: BrandD | L80: 4 | M80: 2008.45 | N80: 5
A81: 10339 | B81: 1147 | C81: 45005 | D81: 45012 | E81: Chennai | F81: Maharashtra | G81: Mobile App | H81: Debit Card | I81: Fashion | J81: Sneakers | K81: BrandA | L81: 4 | M81: 3708.51 | N81: 5
A82: 10347 | B82: 1550 | C82: 44952 | D82: 44954 | E82: Chennai | F82: West Bengal | G82: Website | H82: UPI | I82: Home & Kitchen | J82: Mixer Grinder | K82: BrandC | L82: 4 | M82: 640.37 | N82: 20
A83: 10071 | B83: 1776 | C83: 45070 | D83: 45078 | E83: Chennai | F83: West Bengal | G83: Mobile App | H83: Credit Card | I83: Sports | J83: Cricket Bat | K83: BrandB | L83: 3 | M83: 3854.71 | N83: 5
...

Sheet Operator
B1: Num 1 | C1: Num 2 | D1: opr
B2: 49 | C2: 63 | D2: =B2=C2 -> FALSE
D3: =B2<>C2 -> TRUE

Sheet Classwork
A1: Student ID | B1: Name | C1: Marks | D1: Attendance % | E1: Project Score | F1: Sports Participation | G1: Result1 | H1: Grade | I1: Grade1 | J1: Project Grade | K1: Between 50 to 70 | L1: Project Grade1 | M1: Marks Status
A2: S101 | B2: Amit | C2: 92 | D2: 95 | E2: 88 | F2: Yes | G2: =IF(C2>=50,"Pass","Fail") -> Pass | H2: {=_xlfn.IFS(C2>=90,"A",C2>=70,"B",C2>=50,"C",C2>=40,"Pass",C2<40,"Fail")} -> A | I2: =IF(C2>=90,"A",IF(C2>=70,"B",IF(C2>=50,"C",IF(C2>=40,"Pass","Fail")))) -> A | J2: =IF(E2>=85,"Excellent",IF(E2>=70,"Good",IF(E2>=50,"Average","Poor"))) -> Excellent | K2: =AND(C2>=50,C2<=70) -> FALSE | L2: =IF(AND(C2>=0,C2<40),"Fail",IF(AND(C2>=40,C2<50),"Pass",IF(AND(C2>=50,C2<70),"C",IF(AND(C2>=70,C2<90),"B","A")))) -> A | M2: =IF(OR(C2<=0,C2>=100),"Invalid","Valid") -> Valid
A3: S102 | B3: Riya | C3: 76 | D3: 82 | E3: 70 | F3: No | G3: =IF(C3>=50,"Pass","Fail") -> Pass | H3: {=_xlfn.IFS(C3>=90,"A",C3>=70,"B",C3>=50,"C",C3>=40,"Pass",C3<40,"Fail")} -> B | I3: =IF(C3>=90,"A",IF(C3>=70,"B",IF(C3>=50,"C",IF(C3>=40,"Pass","Fail")))) -> B | J3: =IF(E3>=85,"Excellent",IF(E3>=70,"Good",IF(E3>=50,"Average","Poor"))) -> Good | K3: =AND(C3>=50,C3<=70) -> FALSE | L3: =IF(AND(C3>=0,C3<40),"Fail",IF(AND(C3>=40,C3<50),"Pass",IF(AND(C3>=50,C3<70),"C",IF(AND(C3>=70,C3<90),"B","A")))) -> B | M3: =IF(OR(C3<=0,C3>=100),"Invalid","Valid") -> Valid
A4: S103 | B4: Arjun | C4: 45 | D4: 68 | E4: 55 | F4: Yes | G4: =IF(C4>=50,"Pass","Fail") -> Fail | H4: {=_xlfn.IFS(C4>=90,"A",C4>=70,"B",C4>=50,"C",C4>=40,"Pass",C4<40,"Fail")} -> Pass | I4: =IF(C4>=90,"A",IF(C4>=70,"B",IF(C4>=50,"C",IF(C4>=40,"Pass","Fail")))) -> Pass | J4: =IF(E4>=85,"Excellent",IF(E4>=70,"Good",IF(E4>=50,"Average","Poor"))) -> Average | K4: =AND(C4>=50,C4<=70) -> FALSE | L4: =IF(AND(C4>=0,C4<40),"Fail",IF(AND(C4>=40,C4<50),"Pass",IF(AND(C4>=50,C4<70),"C",IF(AND(C4>=70,C4<90),"B","A")))) -> Pass | M4: =IF(OR(C4<=0,C4>=100),"Invalid","Valid") -> Valid
A5: S104 | B5: Sneha | C5: 59 | D5: 74 | E5: 61 | F5: No | G5: =IF(C5>=50,"Pass","Fail") -> Pass | H5: {=_xlfn.IFS(C5>=90,"A",C5>=70,"B",C5>=50,"C",C5>=40,"Pass",C5<40,"Fail")} -> C | I5: =IF(C5>=90,"A",IF(C5>=70,"B",IF(C5>=50,"C",IF(C5>=40,"Pass","Fail")))) -> C | J5: =IF(E5>=85,"Excellent",IF(E5>=70,"Good",IF(E5>=50,"Average","Poor"))) -> Average | K5: =AND(C5>=50,C5<=70) -> TRUE | L5: =IF(AND(C5>=0,C5<40),"Fail",IF(AND(C5>=40,C5<50),"Pass",IF(AND(C5>=50,C5<70),"C",IF(AND(C5>=70,C5<90),"B","A")))) -> C | M5: =IF(OR(C5<=0,C5>=100),"Invalid","Valid") -> Valid
A6: S105 | B6: Rahul | C6: 81 | D6: 91 | E6: 79 | F6: Yes | G6: =IF(C6>=50,"Pass","Fail") -> Pass | H6: {=_xlfn.IFS(C6>=90,"A",C6>=70,"B",C6>=50,"C",C6>=40,"Pass",C6<40,"Fail")} -> B | I6: =IF(C6>=90,"A",IF(C6>=70,"B",IF(C6>=50,"C",IF(C6>=40,"Pass","Fail")))) -> B | J6: =IF(E6>=85,"Excellent",IF(E6>=70,"Good",IF(E6>=50,"Average","Poor"))) -> Good | K6: =AND(C6>=50,C6<=70) -> FALSE | L6: =IF(AND(C6>=0,C6<40),"Fail",IF(AND(C6>=40,C6<50),"Pass",IF(AND(C6>=50,C6<70),"C",IF(AND(C6>=70,C6<90),"B","A")))) -> B | M6: =IF(OR(C6<=0,C6>=100),"Invalid","Valid") -> Valid
A7: S106 | B7: Priya | C7: 33 | D7: 60 | E7: 40 | F7: No | G7: =IF(C7>=50,"Pass","Fail") -> Fail | H7: {=_xlfn.IFS(C7>=90,"A",C7>=70,"B",C7>=50,"C",C7>=40,"Pass",C7<40,"Fail")} -> Fail | I7: =IF(C7>=90,"A",IF(C7>=70,"B",IF(C7>=50,"C",IF(C7>=40,"Pass","Fail")))) -> Fail | J7: =IF(E7>=85,"Excellent",IF(E7>=70,"Good",IF(E7>=50,"Average","Poor"))) -> Poor | K7: =AND(C7>=50,C7<=70) -> FALSE | L7: =IF(AND(C7>=0,C7<40),"Fail",IF(AND(C7>=40,C7<50),"Pass",IF(AND(C7>=50,C7<70),"C",IF(AND(C7>=70,C7<90),"B","A")))) -> Fail | M7: =IF(OR(C7<=0,C7>=100),"Invalid","Valid") -> Valid
A8: S107 | B8: Karan | C8: 67 | D8: 85 | E8: 72 | F8: Yes | G8: =IF(C8>=50,"Pass","Fail") -> Pass | H8: {=_xlfn.IFS(C8>=90,"A",C8>=70,"B",C8>=50,"C",C8>=40,"Pass",C8<40,"Fail")} -> C | I8: =IF(C8>=90,"A",IF(C8>=70,"B",IF(C8>=50,"C",IF(C8>=40,"Pass","Fail")))) -> C | J8: =IF(E8>=85,"Excellent",IF(E8>=70,"Good",IF(E8>=50,"Average","Poor"))) -> Good | K8: =AND(C8>=50,C8<=70) -> TRUE | L8: =IF(AND(C8>=0,C8<40),"Fail",IF(AND(C8>=40,C8<50),"Pass",IF(AND(C8>=50,C8<70),"C",IF(AND(C8>=70,C8<90),"B","A")))) -> C | M8: =IF(OR(C8<=0,C8>=100),"Invalid","Valid") -> Valid
A9: S108 | B9: Neha | C9: 49 | D9: 71 | E9: 58 | F9: No | G9: =IF(C9>=50,"Pass","Fail") -> Fail | H9: {=_xlfn.IFS(C9>=90,"A",C9>=70,"B",C9>=50,"C",C9>=40,"Pass",C9<40,"Fail")} -> Pass | I9: =IF(C9>=90,"A",IF(C9>=70,"B",IF(C9>=50,"C",IF(C9>=40,"Pass","Fail")))) -> Pass | J9: =IF(E9>=85,"Excellent",IF(E9>=70,"Good",IF(E9>=50,"Average","Poor"))) -> Average | K9: =AND(C9>=50,C9<=70) -> FALSE | L9: =IF(AND(C9>=0,C9<40),"Fail",IF(AND(C9>=40,C9<50),"Pass",IF(AND(C9>=50,C9<70),"C",IF(AND(C9>=70,C9<90),"B","A")))) -> Pass | M9: =IF(OR(C9<=0,C9>=100),"Invalid","Valid") -> Valid
A10: S109 | B10: Vivek | C10: 88 | D10: 97 | E10: 91 | F10: Yes | G10: =IF(C10>=50,"Pass","Fail") -> Pass | H10: {=_xlfn.IFS(C10>=90,"A",C10>=70,"B",C10>=50,"C",C10>=40,"Pass",C10<40,"Fail")} -> B | I10: =IF(C10>=90,"A",IF(C10>=70,"B",IF(C10>=50,"C",IF(C10>=40,"Pass","Fail")))) -> B | J10: =IF(E10>=85,"Excellent",IF(E10>=70,"Good",IF(E10>=50,"Average","Poor"))) -> Excellent | K10: =AND(C10>=50,C10<=70) -> FALSE | L10: =IF(AND(C10>=0,C10<40),"Fail",IF(AND(C10>=40,C10<50),"Pass",IF(AND(C10>=50,C10<70),"C",IF(AND(C10>=70,C10<90),"B","A")))) -> B | M10: =IF(OR(C10<=0,C10>=100),"Invalid","Valid") -> Valid
A11: S110 | B11: Ananya | C11: 54 | D11: 76 | E11: 64 | F11: No | G11: =IF(C11>=50,"Pass","Fail") -> Pass | H11: {=_xlfn.IFS(C11>=90,"A",C11>=70,"B",C11>=50,"C",C11>=40,"Pass",C11<40,"Fail")} -> C | I11: =IF(C11>=90,"A",IF(C11>=70,"B",IF(C11>=50,"C",IF(C11>=40,"Pass","Fail")))) -> C | J11: =IF(E11>=85,"Excellent",IF(E11>=70,"Good",IF(E11>=50,"Average","Poor"))) -> Average | K11: =AND(C11>=50,C11<=70) -> TRUE | L11: =IF(AND(C11>=0,C11<40),"Fail",IF(AND(C11>=40,C11<50),"Pass",IF(AND(C11>=50,C11<70),"C",IF(AND(C11>=70,C11<90),"B","A")))) -> C | M11: =IF(OR(C11<=0,C11>=100),"Invalid","Valid") -> Valid

Sheet COUNT
B2: 1 | C2: Apple | E2: =COUNT(B2:B8) -> 7 | F2: =COUNTA(C2:C8) -> 6 | G2: =COUNTBLANK(C2:C8) -> 1
B3: 2 | C3: Mango
B4: 3 | C4: Lichi
B5: 4 | C5: Apple
B6: 5 | C6: Mango
B7: 6 | C7: Apple
B8: 7

Sheet Cons1
D15: S1 | E15: S2 | F15: S3 | G15: S4
C16: A | D16: 65 | E16: 76 | F16: 56 | G16: 89
C17: B | D17: 98 | E17: 89 | F17: 45 | G17: 68
C18: C | D18: 55 | E18: 90 | F18: 45 | G18: 72
C19: D | D19: 65 | E19: 45 | F19: 98 | G19: 93
C20: E | D20: 67 | E20: 89 | F20: 45 | G20: 70

Sheet Cons2
J1: S1 | K1: S2 | L1: S3 | M1: S4
I2: A | J2: 56 | K2: 78 | L2: 56 | M2: 89
I3: B | J3: 98 | K3: 89 | L3: 45 | M3: 68
I4: C | J4: 55 | K4: 90 | L4: 45 | M4: 72
I5: D | J5: 65 | K5: 45 | L5: 98 | M5: 93
I6: E | J6: 67 | K6: 89 | L6: 45 | M6: 70

Sheet Cons3
J11: S1 | K11: S2 | L11: S3 | M11: S4
I12: A | J12: 56 | K12: 78 | L12: 56 | M12: 89
I13: B | J13: 98 | K13: 89 | L13: 45 | M13: 68
I14: C | J14: 55 | K14: 90 | L14: 45 | M14: 72
I15: D | J15: 65 | K15: 45 | L15: 98 | M15: 93
I16: E | J16: 67 | K16: 89 | L16: 45 | M16: 70

Sheet 3DSum
C2: S1 | D2: S2 | E2: S3 | F2: S4
B3: A | C3: 168 | D3: 234 | E3: 168 | F3: 267
B4: B | C4: 294 | D4: 267 | E4: 135 | F4: 204
B5: C | C5: 165 | D5: 270 | E5: 135 | F5: 216
B6: D | C6: 195 | D6: 135 | E6: 294 | F6: 279
B7: E | C7: 201 | D7: 267 | E7: 135 | F7: 210
K9: S1 | L9: S2 | M9: S3 | N9: S4
J10: Classwork 1 | K10: =Cons1!$D$16 -> 65 | L10: =Cons1!$E$16 -> 76 | M10: =Cons1!$F$16 -> 56 | N10: =Cons1!$G$16 -> 89
J11: Classwork 1 | K11: =Cons2!$J$2 -> 56 | L11: =Cons2!$K$2 -> 78 | M11: =Cons2!$L$2 -> 56 | N11: =Cons2!$M$2 -> 89
J12: Classwork 1 | K12: =Cons3!$J$12 -> 56 | L12: =Cons3!$K$12 -> 78 | M12: =Cons3!$L$12 -> 56 | N12: =Cons3!$M$12 -> 89
I13: A | K13: =SUM(K10:K12) -> 177 | L13: =SUM(L10:L12) -> 232 | M13: =SUM(M10:M12) -> 168 | N13: =SUM(N10:N12) -> 267
J14: Classwork 1 | K14: =Cons1!$D$17 -> 98 | L14: =Cons1!$E$17 -> 89 | M14: =Cons1!$F$17 -> 45 | N14: =Cons1!$G$17 -> 68
J15: Classwork 1 | K15: =Cons2!$J$3 -> 98 | L15: =Cons2!$K$3 -> 89 | M15: =Cons2!$L$3 -> 45 | N15: =Cons2!$M$3 -> 68
J16: Classwork 1 | K16: =Cons3!$J$13 -> 98 | L16: =Cons3!$K$13 -> 89 | M16: =Cons3!$L$13 -> 45 | N16: =Cons3!$M$13 -> 68
I17: B | K17: =SUM(K14:K16) -> 294 | L17: =SUM(L14:L16) -> 267 | M17: =SUM(M14:M16) -> 135 | N17: =SUM(N14:N16) -> 204
J18: Classwork 1 | K18: =Cons1!$D$18 -> 55 | L18: =Cons1!$E$18 -> 90 | M18: =Cons1!$F$18 -> 45 | N18: =Cons1!$G$18 -> 72
J19: Classwork 1 | K19: =Cons2!$J$4 -> 55 | L19: =Cons2!$K$4 -> 90 | M19: =Cons2!$L$4 -> 45 | N19: =Cons2!$M$4 -> 72
J20: Classwork 1 | K20: =Cons3!$J$14 -> 55 | L20: =Cons3!$K$14 -> 90 | M20: =Cons3!$L$14 -> 45 | N20: =Cons3!$M$14 -> 72
I21: C | K21: =SUM(K18:K20) -> 165 | L21: =SUM(L18:L20) -> 270 | M21: =SUM(M18:M20) -> 135 | N21: =SUM(N18:N20) -> 216
J22: Classwork 1 | K22: =Cons1!$D$19 -> 65 | L22: =Cons1!$E$19 -> 45 | M22: =Cons1!$F$19 -> 98 | N22: =Cons1!$G$19 -> 93
J23: Classwork 1 | K23: =Cons2!$J$5 -> 65 | L23: =Cons2!$K$5 -> 45 | M23: =Cons2!$L$5 -> 98 | N23: =Cons2!$M$5 -> 93
J24: Classwork 1 | K24: =Cons3!$J$15 -> 65 | L24: =Cons3!$K$15 -> 45 | M24: =Cons3!$L$15 -> 98 | N24: =Cons3!$M$15 -> 93
I25: D | K25: =SUM(K22:K24) -> 195 | L25: =SUM(L22:L24) -> 135 | M25: =SUM(M22:M24) -> 294 | N25: =SUM(N22:N24) -> 279
J26: Classwork 1 | K26: =Cons1!$D$20 -> 67 | L26: =Cons1!$E$20 -> 89 | M26: =Cons1!$F$20 -> 45 | N26: =Cons1!$G$20 -> 70
J27: Classwork 1 | K27: =Cons2!$J$6 -> 67 | L27: =Cons2!$K$6 -> 89 | M27: =Cons2!$L$6 -> 45 | N27: =Cons2!$M$6 -> 70
J28: Classwork 1 | K28: =Cons3!$J$16 -> 67 | L28: =Cons3!$K$16 -> 89 | M28: =Cons3!$L$16 -> 45 | N28: =Cons3!$M$16 -> 70
I29: E | K29: =SUM(K26:K28) -> 201 | L29: =SUM(L26:L28) -> 267 | M29: =SUM(M26:M28) -> 135 | N29: =SUM(N26:N28) -> 210

Sheet Conditional_Format
A1: Order ID | B1: Customer ID | C1: Order Date | D1: Ship Date | E1: City | F1: State | G1: Sales Channel | H1: Payment Method | I1: Product Category | J1: Product Name | K1: Brand | L1: Units Sold | M1: Unit Price | N1: Discount %
A2: 10001 | B2: 1102 | C2: 45197 | D2: 45203 | E2: Chennai | F2: Delhi | G2: Mobile App | H2: Credit Card | I2: Home & Kitchen | J2: Mixer Grinder | K2: BrandA | L2: 7 | M2: 2843.87 | N2: 0
A3: 10002 | B3: 1435 | C3: 45199 | D3: 45203 | E3: Pune | F3: Tamil Nadu | G3: Website | H3: Debit Card | I3: Sports | J3: Football | K3: BrandD | L3: 9 | M3: 2525.23 | N3: 5 | P3: City | Q3: Hyderabad | T3: Chennai | U3: Home & Kitchen | V3: Mixer Grinder
A4: 10003 | B4: 1860 | C4: 45109 | D4: 45114 | E4: Chennai | F4: West Bengal | G4: Marketplace | H4: Debit Card | I4: Fashion | J4: Sneakers | K4: BrandE | L4: 6 | M4: 3474.34 | N4: 15 | T4: Pune | U4: Sports | V4: Football
A5: 10004 | B5: 1270 | C5: 45079 | D5: 45087 | E5: Bengaluru | F5: West Bengal | G5: Website | H5: Cash on Delivery | I5: Sports | J5: Yoga Mat | K5: BrandA | L5: 1 | M5: 1008.79 | N5: 15 | T5: Bengaluru | U5: Fashion | V5: Sneakers
A6: 10005 | B6: 1106 | C6: 45241 | D6: 45244 | E6: Kolkata | F6: Karnataka | G6: Marketplace | H6: Credit Card | I6: Fashion | J6: Jacket | K6: BrandA | L6: 7 | M6: 3511.47 | N6: 20 | T6: Kolkata | U6: Electronics | V6: Yoga Mat
A7: 10006 | B7: 1071 | C7: 45260 | D7: 45263 | E7: Hyderabad | F7: Telangana | G7: Website | H7: Net Banking | I7: Home & Kitchen | J7: Bedsheet | K7: BrandE | L7: 3 | M7: 3189.55 | N7: 10 | T7: Hyderabad | U7: Beauty | V7: Jacket
A8: 10007 | B8: 1700 | C8: 45050 | D8: 45054 | E8: Bengaluru | F8: Telangana | G8: Mobile App | H8: UPI | I8: Fashion | J8: Sneakers | K8: BrandC | L8: 5 | M8: 3030.42 | N8: 10 | T8: Mumbai | U8: Books | V8: Bedsheet
A9: 10008 | B9: 1020 | C9: 45040 | D9: 45041 | E9: Mumbai | F9: Delhi | G9: Website | H9: Credit Card | I9: Fashion | J9: Sneakers | K9: BrandB | L9: 4 | M9: 2310.83 | N9: 10 | T9: Delhi | V9: T-Shirt
A10: 10009 | B10: 1614 | C10: 45204 | D10: 45213 | E10: Chennai | F10: West Bengal | G10: Website | H10: Debit Card | I10: Fashion | J10: T-Shirt | K10: BrandD | L10: 5 | M10: 1098.04 | N10: 15 | V10: Headphones
A11: 10010 | B11: 1121 | C11: 45139 | D11: 45147 | E11: Bengaluru | F11: Karnataka | G11: Website | H11: Cash on Delivery | I11: Electronics | J11: Headphones | K11: BrandB | L11: 5 | M11: 1780.66 | N11: 20 | V11: Smartwatch
A12: 10011 | B12: 1466 | C12: 45098 | D12: 45106 | E12: Bengaluru | F12: Karnataka | G12: Mobile App | H12: Cash on Delivery | I12: Electronics | J12: Headphones | K12: BrandE | L12: 6 | M12: 3205.25 | N12: 0 | V12: Shampoo
A13: 10012 | B13: 1214 | C13: 45214 | D13: 45220 | E13: Mumbai | F13: Tamil Nadu | G13: Website | H13: UPI | I13: Electronics | J13: Smartwatch | K13: BrandA | L13: 6 | M13: 272.35 | N13: 5 | V13: Curtains
A14: 10013 | B14: 1330 | C14: 45100 | D14: 45107 | E14: Delhi | F14: Tamil Nadu | G14: Mobile App | H14: Cash on Delivery | I14: Home & Kitchen | J14: Bedsheet | K14: BrandA | L14: 8 | M14: 3160.9 | N14: 0 | P14: Product Category | Q14: Product Name | V14: Lipstick
A15: 10014 | B15: 1458 | C15: 45039 | D15: 45045 | E15: Kolkata | F15: Karnataka | G15: Marketplace | H15: Cash on Delivery | I15: Sports | J15: Yoga Mat | K15: BrandD | L15: 8 | M15: 1074.27 | N15: 15 | P15: Home & Kitchen | Q15: Curtains | V15: Fiction Novel
A16: 10015 | B16: 1087 | C16: 45048 | D16: 45057 | E16: Hyderabad | F16: Tamil Nadu | G16: Website | H16: Credit Card | I16: Beauty | J16: Shampoo | K16: BrandA | L16: 9 | M16: 705.59 | N16: 10 | V16: Comics
A17: 10016 | B17: 1372 | C17: 44958 | D17: 44961 | E17: Pune | F17: West Bengal | G17: Mobile App | H17: Net Banking | I17: Fashion | J17: Jacket | K17: BrandA | L17: 8 | M17: 595.45 | N17: 5 | V17: Perfume
A18: 10017 | B18: 1099 | C18: 45148 | D18: 45151 | E18: Delhi | F18: Maharashtra | G18: Mobile App | H18: UPI | I18: Fashion | J18: Jacket | K18: BrandD | L18: 2 | M18: 254.91 | N18: 15 | V18: Cricket Bat
A19: 10018 | B19: 1871 | C19: 45045 | D19: 45048 | E19: Chennai | F19: West Bengal | G19: Website | H19: Credit Card | I19: Home & Kitchen | J19: Curtains | K19: BrandD | L19: 1 | M19: 2165.81 | N19: 15 | V19: Textbook
A20: 10019 | B20: 1663 | C20: 44965 | D20: 44968 | E20: Bengaluru | F20: Karnataka | G20: Marketplace | H20: Net Banking | I20: Fashion | J20: Jacket | K20: BrandE | L20: 2 | M20: 990.3 | N20: 15 | V20: Laptop
A21: 10020 | B21: 1130 | C21: 45194 | D21: 45203 | E21: Mumbai | F21: Karnataka | G21: Mobile App | H21: Credit Card | I21: Electronics | J21: Smartwatch | K21: BrandA | L21: 2 | M21: 3959.31 | N21: 5 | V21: Face Cream
A22: 10021 | B22: 1661 | C22: 45159 | D22: 45163 | E22: Mumbai | F22: West Bengal | G22: Website | H22: Credit Card | I22: Beauty | J22: Lipstick | K22: BrandA | L22: 3 | M22: 2361.58 | N22: 5 | V22: Jeans
A23: 10022 | B23: 1308 | C23: 44944 | D23: 44951 | E23: Kolkata | F23: Tamil Nadu | G23: Marketplace | H23: Cash on Delivery | I23: Books | J23: Fiction Novel | K23: BrandE | L23: 7 | M23: 680.86 | N23: 20 | V23: Biography
A24: 10023 | B24: 1769 | C24: 45075 | D24: 45084 | E24: Delhi | F24: Tamil Nadu | G24: Mobile App | H24: Net Banking | I24: Fashion | J24: Sneakers | K24: BrandC | L24: 2 | M24: 2801.74 | N24: 20 | V24: Smartphone
A25: 10024 | B25: 1343 | C25: 45075 | D25: 45082 | E25: Pune | F25: Telangana | G25: Mobile App | H25: UPI | I25: Electronics | J25: Smartwatch | K25: BrandC | L25: 1 | M25: 3606.31 | N25: 0 | V25: Dumbbells
A26: 10025 | B26: 1491 | C26: 45052 | D26: 45061 | E26: Kolkata | F26: Karnataka | G26: Marketplace | H26: UPI | I26: Books | J26: Comics | K26: BrandC | L26: 6 | M26: 3018.94 | N26: 5 | V26: Cookware Set
A27: 10026 | B27: 1413 | C27: 45228 | D27: 45231 | E27: Bengaluru | F27: Delhi | G27: Marketplace | H27: Net Banking | I27: Beauty | J27: Perfume | K27: BrandE | L27: 9 | M27: 444.29 | N27: 5
A28: 10027 | B28: 1805 | C28: 45286 | D28: 45290 | E28: Kolkata | F28: Telangana | G28: Website | H28: Cash on Delivery | I28: Books | J28: Fiction Novel | K28: BrandA | L28: 3 | M28: 3599.15 | N28: 5
A29: 10028 | B29: 1385 | C29: 45164 | D29: 45172 | E29: Hyderabad | F29: Tamil Nadu | G29: Website | H29: Debit Card | I29: Electronics | J29: Smartwatch | K29: BrandE | L29: 6 | M29: 3206.63 | N29: 20
A30: 10029 | B30: 1191 | C30: 45061 | D30: 45067 | E30: Mumbai | F30: West Bengal | G30: Mobile App | H30: Credit Card | I30: Sports | J30: Football | K30: BrandE | L30: 3 | M30: 759.47 | N30: 15
A31: 10030 | B31: 1955 | C31: 45077 | D31: 45082 | E31: Mumbai | F31: Tamil Nadu | G31: Marketplace | H31: Cash on Delivery | I31: Sports | J31: Cricket Bat | K31: BrandC | L31: 1 | M31: 349.38 | N31: 10
A32: 10031 | B32: 1276 | C32: 45162 | D32: 45166 | E32: Chennai | F32: West Bengal | G32: Marketplace | H32: Net Banking | I32: Books | J32: Textbook | K32: BrandB | L32: 5 | M32: 2295.65 | N32: 20
A33: 10032 | B33: 1160 | C33: 45150 | D33: 45158 | E33: Chennai | F33: Telangana | G33: Marketplace | H33: Credit Card | I33: Home & Kitchen | J33: Bedsheet | K33: BrandA | L33: 4 | M33: 750.74 | N33: 5
A34: 10033 | B34: 1459 | C34: 45129 | D34: 45130 | E34: Pune | F34: Karnataka | G34: Mobile App | H34: UPI | I34: Books | J34: Comics | K34: BrandC | L34: 7 | M34: 3363.18 | N34: 20
A35: 10034 | B35: 1313 | C35: 45182 | D35: 45191 | E35: Bengaluru | F35: Tamil Nadu | G35: Marketplace | H35: Debit Card | I35: Fashion | J35: T-Shirt | K35: BrandB | L35: 6 | M35: 1529.59 | N35: 0
A36: 10035 | B36: 1021 | C36: 45012 | D36: 45013 | E36: Hyderabad | F36: West Bengal | G36: Marketplace | H36: UPI | I36: Fashion | J36: T-Shirt | K36: BrandB | L36: 7 | M36: 3664.64 | N36: 5
A37: 10036 | B37: 1252 | C37: 45076 | D37: 45084 | E37: Delhi | F37: Karnataka | G37: Mobile App | H37: Net Banking | I37: Sports | J37: Football | K37: BrandD | L37: 5 | M37: 2327.9 | N37: 0
A38: 10037 | B38: 1747 | C38: 45161 | D38: 45165 | E38: Kolkata | F38: Delhi | G38: Website | H38: Credit Card | I38: Home & Kitchen | J38: Curtains | K38: BrandA | L38: 4 | M38: 853.29 | N38: 5
... A373: 10500 | B373: 1569 | C373: 44972 | D373: 44977 | E373: Chennai | F373: Delhi | G373: Marketplace | H373: Net Banking | I373: Fashion | J373: Jeans | K373: BrandE | L373: 1 | M373: 2432.17 | N373: 20
